from django.core.exceptions import ValidationError
from django.db import models


class Tag(models.Model):
    name = models.CharField(max_length=100, verbose_name='Тэг')

    class Meta:
        verbose_name = 'Тэг'
        verbose_name_plural = 'Тэги'
        ordering = ['name']

    def __str__(self):
        return self.name


class Article(models.Model):
    title = models.CharField(max_length=256, verbose_name='Название')
    text = models.TextField(verbose_name='Текст')
    published_at = models.DateTimeField(verbose_name='Дата публикации')
    image = models.ImageField(null=True, blank=True, verbose_name='Изображение', )
    tags = models.ManyToManyField(Tag, through='Scope', related_name='articles')

    class Meta:
        verbose_name = 'Статья'
        verbose_name_plural = 'Статьи'
        ordering = ['-published_at']

    def __str__(self):
        return self.title


class Scope(models.Model):
    article = models.ForeignKey(Article, on_delete=models.PROTECT, related_name='scopes')
    tag = models.ForeignKey(Tag, on_delete=models.PROTECT, verbose_name='РАЗДЕЛ')
    is_main = models.BooleanField(verbose_name='Основной')

    class Meta:
        verbose_name = 'Тематика статьи'
        verbose_name_plural = 'ТЕМАТИКИ СТАТЬИ'
        ordering = ['-is_main', 'tag']



